Workbook
Name PRIMERO: BANCO!$E$4:$F$63
Name RESPUESTAS: BANCO!$B$4:$C$153
Name SEGUNDO: BANCO!$H$4:$I$73

Sheet RespuestasCorrectas
A1: Pregunta_1 | B1: Pregunta_2 | C1: Pregunta_3 | D1: Pregunta_4 | E1: Pregunta_5 | F1: Pregunta_6 | G1: Pregunta_7 | H1: Pregunta_8 | I1: Pregunta_9 | J1: Pregunta_10 | K1: Pregunta_11 | L1: Pregunta_12 | M1: Pregunta_13 | N1: Pregunta_14 | O1: Pregunta_15 | P1: Pregunta_16 | Q1: Pregunta_17 | R1: Pregunta_18 | S1: Pregunta_19 | T1: Pregunta_20 | U1: Pregunta_21 | V1: Pregunta_22 | W1: Pregunta_23 | X1: Pregunta_24 | Y1: Pregunta_25 | Z1: Pregunta_26 | AA1: Pregunta_27 | AB1: Pregunta_28 | AC1: Pregunta_29 | AD1: Pregunta_30 | AE1: Pregunta_31 | AF1: Pregunta_32 | AG1: Pregunta_33 | AH1: Pregunta_34 | AI1: Pregunta_35 | AJ1: Pregunta_36 | AK1: Pregunta_37 | AL1: Pregunta_38 | AM1: Pregunta_39 | AN1: Pregunta_40 | AO1: Pregunta_41 | AP1: Pregunta_42 | AQ1: Pregunta_43 | AR1: Pregunta_44 | AS1: Pregunta_45 | AT1: Pregunta_46 | AU1: Pregunta_47 | AV1: Pregunta_48 | AW1: Pregunta_49 | AX1: Pregunta_50 | AY1: Pregunta_51 | AZ1: Pregunta_52 | BA1: Pregunta_53 | BB1: Pregunta_54 | BC1: Pregunta_55 | BD1: Pregunta_56 | BE1: Pregunta_57 | BF1: Pregunta_58 | BG1: Pregunta_59 | BH1: Pregunta_60 | BI1: Pregunta_61 | BJ1: Pregunta_62 | BK1: Pregunta_63 | BL1: Pregunta_64 | BM1: Pregunta_65 | BN1: Pregunta_66 | BO1: Pregunta_67 | BP1: Pregunta_68 | BQ1: Pregunta_69 | BR1: Pregunta_70 | BS1: Pregunta_71 | BT1: Pregunta_72 | BU1: Pregunta_73 | BV1: Pregunta_74 | BW1: Pregunta_75 | BX1: Pregunta_76 | BY1: Pregunta_77 | BZ1: Pregunta_78 | CA1: Pregunta_79 | CB1: Pregunta_80 | CC1: Pregunta_81 | CD1: Pregunta_82 | CE1: Pregunta_83 | CF1: Pregunta_84 | CG1: Pregunta_85 | CH1: Pregunta_86 | CI1: Pregunta_87 | CJ1: Pregunta_88 | CK1: Pregunta_89 | CL1: Pregunta_90 | CM1: Pregunta_91 | CN1: Pregunta_92 | CO1: Pregunta_93 | CP1: Pregunta_94 | CQ1: Pregunta_95 | CR1: Pregunta_96 | CS1: Pregunta_97 | CT1: Pregunta_98 | CU1: Pregunta_99 | CV1: Pregunta_100 | CW1: Pregunta_101 | CX1: Pregunta_102 | CY1: Pregunta_103 | CZ1: Pregunta_104 | DA1: Pregunta_105 | DB1: Pregunta_106 | DC1: Pregunta_107 | DD1: Pregunta_108 | DE1: Pregunta_109 | DF1: Pregunta_110 | DG1: Pregunta_111 | DH1: Pregunta_112 | DI1: Pregunta_113 | DJ1: Pregunta_114 | DK1: Pregunta_115 | DL1: Pregunta_116 | DM1: Pregunta_117 | DN1: Pregunta_118 | DO1: Pregunta_119 | DP1: Pregunta_120
A2: =VLOOKUP(RespuestasCorrectas!A1,RESPUESTAS,2,FALSE) -> B | B2: =VLOOKUP(RespuestasCorrectas!B1,RESPUESTAS,2,FALSE) -> D | C2: =VLOOKUP(RespuestasCorrectas!C1,RESPUESTAS,2,FALSE) -> C | D2: =VLOOKUP(RespuestasCorrectas!D1,RESPUESTAS,2,FALSE) -> A | E2: =VLOOKUP(RespuestasCorrectas!E1,RESPUESTAS,2,FALSE) -> C | F2: =VLOOKUP(RespuestasCorrectas!F1,RESPUESTAS,2,FALSE) -> B | G2: =VLOOKUP(RespuestasCorrectas!G1,RESPUESTAS,2,FALSE) -> A | H2: =VLOOKUP(RespuestasCorrectas!H1,RESPUESTAS,2,FALSE) -> C | ... DP2: =VLOOKUP(RespuestasCorrectas!DP1,RESPUESTAS,2,FALSE) -> 0

Sheet BANCO
B1: ELEGIR GRADO
B2: 8 | E2: 1 | H2: 2 | K2: 3 | N2: 4 | Q2: 5 | T2: 6 | W2: 7 | Z2: 8 | AC2: 9 | AF2: 10 | AI2: 11
B3: ITEM | C3: CLAVE | E3: ITEM | F3: CLAVE | H3: ITEM | I3: CLAVE | K3: ITEM | L3: CLAVE | N3: ITEM | O3: CLAVE | Q3: ITEM | R3: CLAVE | T3: ITEM | U3: CLAVE | W3: ITEM | X3: CLAVE | Z3: ITEM | AA3: CLAVE | AC3: ITEM | AD3: CLAVE | AF3: ITEM | AG3: CLAVE | AI3: ITEM | AJ3: CLAVE
B4: Pregunta_1 | C4: {=_xlfn.IFS(B$2=1,F4,B$2=2,I4,B$2=3,L4,B$2=4,O4,B$2=5,R4,B$2=6,U4,B$2=7,X4,B$2=8,AA4,B$2=9,AD4,B$2=10,AG4,B$2=11,AJ4)} -> B | E4: Pregunta_1 | F4: A | H4: Pregunta_1 | I4: A | K4: Pregunta_1 | L4: B | N4: Pregunta_1 | O4: B | Q4: Pregunta_1 | R4: A | T4: Pregunta_1 | U4: B | W4: Pregunta_1 | X4: B | Z4: Pregunta_1 | AA4: B | AC4: Pregunta_1 | AD4: B | AF4: Pregunta_1 | AG4: B | AI4: Pregunta_1 | AJ4: B
B5: Pregunta_2 | C5: {=_xlfn.IFS(B$2=1,F5,B$2=2,I5,B$2=3,L5,B$2=4,O5,B$2=5,R5,B$2=6,U5,B$2=7,X5,B$2=8,AA5,B$2=9,AD5,B$2=10,AG5,B$2=11,AJ5)} -> D | E5: Pregunta_2 | F5: B | H5: Pregunta_2 | I5: B | K5: Pregunta_2 | L5: A | N5: Pregunta_2 | O5: B | Q5: Pregunta_2 | R5: C | T5: Pregunta_2 | U5: C | W5: Pregunta_2 | X5: C | Z5: Pregunta_2 | AA5: D | AC5: Pregunta_2 | AD5: C | AF5: Pregunta_2 | AG5: C
B6: Pregunta_3 | C6: {=_xlfn.IFS(B$2=1,F6,B$2=2,I6,B$2=3,L6,B$2=4,O6,B$2=5,R6,B$2=6,U6,B$2=7,X6,B$2=8,AA6,B$2=9,AD6,B$2=10,AG6,B$2=11,AJ6)} -> C | E6: Pregunta_3 | F6: B | H6: Pregunta_3 | I6: B | K6: Pregunta_3 | L6: C | N6: Pregunta_3 | O6: B | Q6: Pregunta_3 | R6: B | T6: Pregunta_3 | U6: B | W6: Pregunta_3 | X6: A | Z6: Pregunta_3 | AA6: C | AC6: Pregunta_3 | AD6: C | AF6: Pregunta_3 | AG6: D
B7: Pregunta_4 | C7: {=_xlfn.IFS(B$2=1,F7,B$2=2,I7,B$2=3,L7,B$2=4,O7,B$2=5,R7,B$2=6,U7,B$2=7,X7,B$2=8,AA7,B$2=9,AD7,B$2=10,AG7,B$2=11,AJ7)} -> A | E7: Pregunta_4 | F7: B | H7: Pregunta_4 | I7: C | K7: Pregunta_4 | L7: A | N7: Pregunta_4 | O7: B | Q7: Pregunta_4 | R7: B | T7: Pregunta_4 | U7: D | W7: Pregunta_4 | X7: B | Z7: Pregunta_4 | AA7: A | AC7: Pregunta_4 | AD7: A | AF7: Pregunta_4 | AG7: C
B8: Pregunta_5 | C8: {=_xlfn.IFS(B$2=1,F8,B$2=2,I8,B$2=3,L8,B$2=4,O8,B$2=5,R8,B$2=6,U8,B$2=7,X8,B$2=8,AA8,B$2=9,AD8,B$2=10,AG8,B$2=11,AJ8)} -> C | E8: Pregunta_5 | F8: C | H8: Pregunta_5 | I8: C | K8: Pregunta_5 | L8: D | N8: Pregunta_5 | O8: C | Q8: Pregunta_5 | R8: C | T8: Pregunta_5 | U8: C | W8: Pregunta_5 | X8: B | Z8: Pregunta_5 | AA8: C | AC8: Pregunta_5 | AD8: B | AF8: Pregunta_5 | AG8: C
B9: Pregunta_6 | C9: {=_xlfn.IFS(B$2=1,F9,B$2=2,I9,B$2=3,L9,B$2=4,O9,B$2=5,R9,B$2=6,U9,B$2=7,X9,B$2=8,AA9,B$2=9,AD9,B$2=10,AG9,B$2=11,AJ9)} -> B | E9: Pregunta_6 | F9: A | H9: Pregunta_6 | I9: C | K9: Pregunta_6 | L9: B | N9: Pregunta_6 | O9: C | Q9: Pregunta_6 | R9: A | T9: Pregunta_6 | U9: D | W9: Pregunta_6 | X9: B | Z9: Pregunta_6 | AA9: B | AC9: Pregunta_6 | AD9: A | AF9: Pregunta_6 | AG9: C
B10: Pregunta_7 | C10: {=_xlfn.IFS(B$2=1,F10,B$2=2,I10,B$2=3,L10,B$2=4,O10,B$2=5,R10,B$2=6,U10,B$2=7,X10,B$2=8,AA10,B$2=9,AD10,B$2=10,AG10,B$2=11,AJ10)} -> A | E10: Pregunta_7 | F10: C | H10: Pregunta_7 | I10: B | K10: Pregunta_7 | L10: A | N10: Pregunta_7 | O10: D | Q10: Pregunta_7 | R10: A | T10: Pregunta_7 | U10: A | W10: Pregunta_7 | X10: B | Z10: Pregunta_7 | AA10: A | AC10: Pregunta_7 | AD10: B | AF10: Pregunta_7 | AG10: B
B11: Pregunta_8 | C11: {=_xlfn.IFS(B$2=1,F11,B$2=2,I11,B$2=3,L11,B$2=4,O11,B$2=5,R11,B$2=6,U11,B$2=7,X11,B$2=8,AA11,B$2=9,AD11,B$2=10,AG11,B$2=11,AJ11)} -> C | E11: Pregunta_8 | F11: A | H11: Pregunta_8 | I11: A | K11: Pregunta_8 | L11: B | N11: Pregunta_8 | O11: B | Q11: Pregunta_8 | R11: A | T11: Pregunta_8 | U11: C | W11: Pregunta_8 | X11: B | Z11: Pregunta_8 | AA11: C | AC11: Pregunta_8 | AD11: A | AF11: Pregunta_8 | AG11: B
B12: Pregunta_9 | C12: {=_xlfn.IFS(B$2=1,F12,B$2=2,I12,B$2=3,L12,B$2=4,O12,B$2=5,R12,B$2=6,U12,B$2=7,X12,B$2=8,AA12,B$2=9,AD12,B$2=10,AG12,B$2=11,AJ12)} -> C | E12: Pregunta_9 | F12: C | H12: Pregunta_9 | I12: C | K12: Pregunta_9 | L12: D | N12: Pregunta_9 | O12: B | Q12: Pregunta_9 | R12: D | T12: Pregunta_9 | U12: C | W12: Pregunta_9 | X12: A | Z12: Pregunta_9 | AA12: C | AC12: Pregunta_9 | AD12: A | AF12: Pregunta_9 | AG12: C
B13: Pregunta_10 | C13: {=_xlfn.IFS(B$2=1,F13,B$2=2,I13,B$2=3,L13,B$2=4,O13,B$2=5,R13,B$2=6,U13,B$2=7,X13,B$2=8,AA13,B$2=9,AD13,B$2=10,AG13,B$2=11,AJ13)} -> A | E13: Pregunta_10 | F13: C | H13: Pregunta_10 | I13: A | K13: Pregunta_10 | L13: C | N13: Pregunta_10 | O13: C | Q13: Pregunta_10 | R13: A | T13: Pregunta_10 | U13: A | W13: Pregunta_10 | X13: D | Z13: Pregunta_10 | AA13: A | AC13: Pregunta_10 | AD13: D | AF13: Pregunta_10 | AG13: C
B14: Pregunta_11 | C14: {=_xlfn.IFS(B$2=1,F14,B$2=2,I14,B$2=3,L14,B$2=4,O14,B$2=5,R14,B$2=6,U14,B$2=7,X14,B$2=8,AA14,B$2=9,AD14,B$2=10,AG14,B$2=11,AJ14)} -> B | E14: Pregunta_11 | F14: B | H14: Pregunta_11 | I14: B | K14: Pregunta_11 | L14: C | N14: Pregunta_11 | O14: D | Q14: Pregunta_11 | R14: D | T14: Pregunta_11 | U14: C | W14: Pregunta_11 | X14: C | Z14: Pregunta_11 | AA14: B | AC14: Pregunta_11 | AD14: A | AF14: Pregunta_11 | AG14: B
B15: Pregunta_12 | C15: {=_xlfn.IFS(B$2=1,F15,B$2=2,I15,B$2=3,L15,B$2=4,O15,B$2=5,R15,B$2=6,U15,B$2=7,X15,B$2=8,AA15,B$2=9,AD15,B$2=10,AG15,B$2=11,AJ15)} -> D | E15: Pregunta_12 | F15: C | H15: Pregunta_12 | I15: C | K15: Pregunta_12 | L15: C | N15: Pregunta_12 | O15: C | Q15: Pregunta_12 | R15: A | T15: Pregunta_12 | U15: C | W15: Pregunta_12 | X15: B | Z15: Pregunta_12 | AA15: D | AC15: Pregunta_12 | AD15: C | AF15: Pregunta_12 | AG15: C
B16: Pregunta_13 | C16: {=_xlfn.IFS(B$2=1,F16,B$2=2,I16,B$2=3,L16,B$2=4,O16,B$2=5,R16,B$2=6,U16,B$2=7,X16,B$2=8,AA16,B$2=9,AD16,B$2=10,AG16,B$2=11,AJ16)} -> C | E16: Pregunta_13 | F16: B | H16: Pregunta_13 | I16: C | K16: Pregunta_13 | L16: C | N16: Pregunta_13 | O16: A | Q16: Pregunta_13 | R16: D | T16: Pregunta_13 | U16: B | W16: Pregunta_13 | X16: D | Z16: Pregunta_13 | AA16: C | AC16: Pregunta_13 | AD16: C | AF16: Pregunta_13 | AG16: C
... B63: Pregunta_60 | C63: {=_xlfn.IFS(B$2=1,F63,B$2=2,I63,B$2=3,L63,B$2=4,O63,B$2=5,R63,B$2=6,U63,B$2=7,X63,B$2=8,AA63,B$2=9,AD63,B$2=10,AG63,B$2=11,AJ63)} -> C | E63: Pregunta_60 | F63: C | H63: Pregunta_60 | I63: A | K63: Pregunta_60 | L63: D | N63: Pregunta_60 | O63: D | Q63: Pregunta_60 | R63: B | T63: Pregunta_60 | U63: A | W63: Pregunta_60 | X63: A | Z63: Pregunta_60 | AA63: C | AC63: Pregunta_60 | AD63: D | AF63: Pregunta_60 | AG63: B
B64: Pregunta_61 | C64: {=_xlfn.IFS(B$2=1,F64,B$2=2,I64,B$2=3,L64,B$2=4,O64,B$2=5,R64,B$2=6,U64,B$2=7,X64,B$2=8,AA64,B$2=9,AD64,B$2=10,AG64,B$2=11,AJ64)} -> A | H64: Pregunta_61 | I64: C | K64: Pregunta_61 | L64: D | N64: Pregunta_61 | O64: D | Q64: Pregunta_61 | R64: B | T64: Pregunta_61 | U64: B | W64: Pregunta_61 | X64: B | Z64: Pregunta_61 | AA64: A | AC64: Pregunta_61 | AD64: C | AF64: Pregunta_61 | AG64: B
B65: Pregunta_62 | C65: {=_xlfn.IFS(B$2=1,F65,B$2=2,I65,B$2=3,L65,B$2=4,O65,B$2=5,R65,B$2=6,U65,B$2=7,X65,B$2=8,AA65,B$2=9,AD65,B$2=10,AG65,B$2=11,AJ65)} -> A | H65: Pregunta_62 | I65: B | K65: Pregunta_62 | L65: A | N65: Pregunta_62 | O65: A | Q65: Pregunta_62 | R65: C | T65: Pregunta_62 | U65: D | W65: Pregunta_62 | X65: C | Z65: Pregunta_62 | AA65: A | AC65: Pregunta_62 | AD65: A | AF65: Pregunta_62 | AG65: A
B66: Pregunta_63 | C66: {=_xlfn.IFS(B$2=1,F66,B$2=2,I66,B$2=3,L66,B$2=4,O66,B$2=5,R66,B$2=6,U66,B$2=7,X66,B$2=8,AA66,B$2=9,AD66,B$2=10,AG66,B$2=11,AJ66)} -> A | H66: Pregunta_63 | I66: A | K66: Pregunta_63 | L66: A | N66: Pregunta_63 | O66: A | Q66: Pregunta_63 | R66: A | T66: Pregunta_63 | U66: D | W66: Pregunta_63 | X66: D | Z66: Pregunta_63 | AA66: A | AC66: Pregunta_63 | AD66: C | AF66: Pregunta_63 | AG66: C
B67: Pregunta_64 | C67: {=_xlfn.IFS(B$2=1,F67,B$2=2,I67,B$2=3,L67,B$2=4,O67,B$2=5,R67,B$2=6,U67,B$2=7,X67,B$2=8,AA67,B$2=9,AD67,B$2=10,AG67,B$2=11,AJ67)} -> C | H67: Pregunta_64 | I67: B | K67: Pregunta_64 | L67: A | N67: Pregunta_64 | O67: A | Q67: Pregunta_64 | R67: C | T67: Pregunta_64 | U67: B | W67: Pregunta_64 | X67: C | Z67: Pregunta_64 | AA67: C | AC67: Pregunta_64 | AD67: C | AF67: Pregunta_64 | AG67: D
B68: Pregunta_65 | C68: {=_xlfn.IFS(B$2=1,F68,B$2=2,I68,B$2=3,L68,B$2=4,O68,B$2=5,R68,B$2=6,U68,B$2=7,X68,B$2=8,AA68,B$2=9,AD68,B$2=10,AG68,B$2=11,AJ68)} -> B | H68: Pregunta_65 | I68: C | K68: Pregunta_65 | L68: A | N68: Pregunta_65 | O68: A | Q68: Pregunta_65 | R68: A | T68: Pregunta_65 | U68: C | W68: Pregunta_65 | X68: A | Z68: Pregunta_65 | AA68: B | AC68: Pregunta_65 | AD68: C | AF68: Pregunta_65 | AG68: A
B69: Pregunta_66 | C69: {=_xlfn.IFS(B$2=1,F69,B$2=2,I69,B$2=3,L69,B$2=4,O69,B$2=5,R69,B$2=6,U69,B$2=7,X69,B$2=8,AA69,B$2=9,AD69,B$2=10,AG69,B$2=11,AJ69)} -> A | H69: Pregunta_66 | I69: A | K69: Pregunta_66 | L69: B | N69: Pregunta_66 | O69: B | Q69: Pregunta_66 | R69: D | T69: Pregunta_66 | U69: D | W69: Pregunta_66 | X69: C | Z69: Pregunta_66 | AA69: A | AC69: Pregunta_66 | AD69: C | AF69: Pregunta_66 | AG69: C
B70: Pregunta_67 | C70: {=_xlfn.IFS(B$2=1,F70,B$2=2,I70,B$2=3,L70,B$2=4,O70,B$2=5,R70,B$2=6,U70,B$2=7,X70,B$2=8,AA70,B$2=9,AD70,B$2=10,AG70,B$2=11,AJ70)} -> C | H70: Pregunta_67 | I70: C | K70: Pregunta_67 | L70: C | N70: Pregunta_67 | O70: C | Q70: Pregunta_67 | R70: B | T70: Pregunta_67 | U70: C | W70: Pregunta_67 | X70: B | Z70: Pregunta_67 | AA70: C | AC70: Pregunta_67 | AD70: A | AF70: Pregunta_67 | AG70: A
B71: Pregunta_68 | C71: {=_xlfn.IFS(B$2=1,F71,B$2=2,I71,B$2=3,L71,B$2=4,O71,B$2=5,R71,B$2=6,U71,B$2=7,X71,B$2=8,AA71,B$2=9,AD71,B$2=10,AG71,B$2=11,AJ71)} -> A | H71: Pregunta_68 | I71: B | K71: Pregunta_68 | L71: C | N71: Pregunta_68 | O71: C | Q71: Pregunta_68 | R71: B | T71: Pregunta_68 | U71: D | W71: Pregunta_68 | X71: C | Z71: Pregunta_68 | AA71: A | AC71: Pregunta_68 | AD71: D | AF71: Pregunta_68 | AG71: D
B72: Pregunta_69 | C72: {=_xlfn.IFS(B$2=1,F72,B$2=2,I72,B$2=3,L72,B$2=4,O72,B$2=5,R72,B$2=6,U72,B$2=7,X72,B$2=8,AA72,B$2=9,AD72,B$2=10,AG72,B$2=11,AJ72)} -> D | H72: Pregunta_69 | I72: A | K72: Pregunta_69 | L72: C | N72: Pregunta_69 | O72: C | Q72: Pregunta_69 | R72: D | T72: Pregunta_69 | U72: A | W72: Pregunta_69 | X72: B | Z72: Pregunta_69 | AA72: D | AC72: Pregunta_69 | AD72: C | AF72: Pregunta_69 | AG72: A
B73: Pregunta_70 | C73: {=_xlfn.IFS(B$2=1,F73,B$2=2,I73,B$2=3,L73,B$2=4,O73,B$2=5,R73,B$2=6,U73,B$2=7,X73,B$2=8,AA73,B$2=9,AD73,B$2=10,AG73,B$2=11,AJ73)} -> B | H73: Pregunta_70 | I73: B | K73: Pregunta_70 | L73: A | N73: Pregunta_70 | O73: A | Q73: Pregunta_70 | R73: C | T73: Pregunta_70 | U73: C | W73: Pregunta_70 | X73: B | Z73: Pregunta_70 | AA73: B | AC73: Pregunta_70 | AD73: B | AF73: Pregunta_70 | AG73: A
B74: Pregunta_71 | C74: {=_xlfn.IFS(B$2=1,F74,B$2=2,I74,B$2=3,L74,B$2=4,O74,B$2=5,R74,B$2=6,U74,B$2=7,X74,B$2=8,AA74,B$2=9,AD74,B$2=10,AG74,B$2=11,AJ74)} -> B | K74: Pregunta_71 | L74: A | N74: Pregunta_71 | O74: A | Q74: Pregunta_71 | R74: D | T74: Pregunta_71 | U74: B | W74: Pregunta_71 | X74: B | Z74: Pregunta_71 | AA74: B | AC74: Pregunta_71 | AD74: B | AF74: Pregunta_71 | AG74: B
B75: Pregunta_72 | C75: {=_xlfn.IFS(B$2=1,F75,B$2=2,I75,B$2=3,L75,B$2=4,O75,B$2=5,R75,B$2=6,U75,B$2=7,X75,B$2=8,AA75,B$2=9,AD75,B$2=10,AG75,B$2=11,AJ75)} -> A | K75: Pregunta_72 | L75: C | N75: Pregunta_72 | O75: C | Q75: Pregunta_72 | R75: B | T75: Pregunta_72 | U75: C | W75: Pregunta_72 | X75: A | Z75: Pregunta_72 | AA75: A | AC75: Pregunta_72 | AD75: B | AF75: Pregunta_72 | AG75: A
B76: Pregunta_73 | C76: {=_xlfn.IFS(B$2=1,F76,B$2=2,I76,B$2=3,L76,B$2=4,O76,B$2=5,R76,B$2=6,U76,B$2=7,X76,B$2=8,AA76,B$2=9,AD76,B$2=10,AG76,B$2=11,AJ76)} -> A | K76: Pregunta_73 | L76: A | N76: Pregunta_73 | O76: A | Q76: Pregunta_73 | R76: B | T76: Pregunta_73 | U76: B | W76: Pregunta_73 | X76: C | Z76: Pregunta_73 | AA76: A | AC76: Pregunta_73 | AD76: C | AF76: Pregunta_73 | AG76: D
B77: Pregunta_74 | C77: {=_xlfn.IFS(B$2=1,F77,B$2=2,I77,B$2=3,L77,B$2=4,O77,B$2=5,R77,B$2=6,U77,B$2=7,X77,B$2=8,AA77,B$2=9,AD77,B$2=10,AG77,B$2=11,AJ77)} -> C | K77: Pregunta_74 | L77: C | N77: Pregunta_74 | O77: C | Q77: Pregunta_74 | R77: D | T77: Pregunta_74 | U77: B | W77: Pregunta_74 | X77: B | Z77: Pregunta_74 | AA77: C | AC77: Pregunta_74 | AD77: A | AF77: Pregunta_74 | AG77: C
B78: Pregunta_75 | C78: {=_xlfn.IFS(B$2=1,F78,B$2=2,I78,B$2=3,L78,B$2=4,O78,B$2=5,R78,B$2=6,U78,B$2=7,X78,B$2=8,AA78,B$2=9,AD78,B$2=10,AG78,B$2=11,AJ78)} -> A | K78: Pregunta_75 | L78: B | N78: Pregunta_75 | O78: A | Q78: Pregunta_75 | R78: C | T78: Pregunta_75 | U78: B | W78: Pregunta_75 | X78: B | Z78: Pregunta_75 | AA78: A | AC78: Pregunta_75 | AD78: B | AF78: Pregunta_75 | AG78: A
B79: Pregunta_76 | C79: {=_xlfn.IFS(B$2=1,F79,B$2=2,I79,B$2=3,L79,B$2=4,O79,B$2=5,R79,B$2=6,U79,B$2=7,X79,B$2=8,AA79,B$2=9,AD79,B$2=10,AG79,B$2=11,AJ79)} -> B | K79: Pregunta_76 | L79: A | N79: Pregunta_76 | O79: A | Q79: Pregunta_76 | R79: B | T79: Pregunta_76 | U79: B | W79: Pregunta_76 | X79: A | Z79: Pregunta_76 | AA79: B | AC79: Pregunta_76 | AD79: A | AF79: Pregunta_76 | AG79: D
B80: Pregunta_77 | C80: {=_xlfn.IFS(B$2=1,F80,B$2=2,I80,B$2=3,L80,B$2=4,O80,B$2=5,R80,B$2=6,U80,B$2=7,X80,B$2=8,AA80,B$2=9,AD80,B$2=10,AG80,B$2=11,AJ80)} -> A | K80: Pregunta_77 | L80: D | N80: Pregunta_77 | O80: D | Q80: Pregunta_77 | R80: C | T80: Pregunta_77 | U80: A | W80: Pregunta_77 | X80: C | Z80: Pregunta_77 | AA80: A | AC80: Pregunta_77 | AD80: C | AF80: Pregunta_77 | AG80: C
B81: Pregunta_78 | C81: {=_xlfn.IFS(B$2=1,F81,B$2=2,I81,B$2=3,L81,B$2=4,O81,B$2=5,R81,B$2=6,U81,B$2=7,X81,B$2=8,AA81,B$2=9,AD81,B$2=10,AG81,B$2=11,AJ81)} -> C | K81: Pregunta_78 | L81: B | N81: Pregunta_78 | O81: B | Q81: Pregunta_78 | R81: D | T81: Pregunta_78 | U81: C | W81: Pregunta_78 | X81: A | Z81: Pregunta_78 | AA81: C | AC81: Pregunta_78 | AD81: A | AF81: Pregunta_78 | AG81: D
B82: Pregunta_79 | C82: {=_xlfn.IFS(B$2=1,F82,B$2=2,I82,B$2=3,L82,B$2=4,O82,B$2=5,R82,B$2=6,U82,B$2=7,X82,B$2=8,AA82,B$2=9,AD82,B$2=10,AG82,B$2=11,AJ82)} -> C | K82: Pregunta_79 | L82: D | N82: Pregunta_79 | O82: D | Q82: Pregunta_79 | R82: C | T82: Pregunta_79 | U82: A | W82: Pregunta_79 | X82: C | Z82: Pregunta_79 | AA82: C | AC82: Pregunta_79 | AD82: B | AF82: Pregunta_79 | AG82: B
B83: Pregunta_80 | C83: {=_xlfn.IFS(B$2=1,F83,B$2=2,I83,B$2=3,L83,B$2=4,O83,B$2=5,R83,B$2=6,U83,B$2=7,X83,B$2=8,AA83,B$2=9,AD83,B$2=10,AG83,B$2=11,AJ83)} -> A | K83: Pregunta_80 | L83: B | N83: Pregunta_80 | O83: B | Q83: Pregunta_80 | R83: A | T83: Pregunta_80 | U83: B | W83: Pregunta_80 | X83: C | Z83: Pregunta_80 | AA83: A | AC83: Pregunta_80 | AD83: C | AF83: Pregunta_80 | AG83: A
B84: Pregunta_81 | C84: {=_xlfn.IFS(B$2=1,F84,B$2=2,I84,B$2=3,L84,B$2=4,O84,B$2=5,R84,B$2=6,U84,B$2=7,X84,B$2=8,AA84,B$2=9,AD84,B$2=10,AG84,B$2=11,AJ84)} -> 0 | AF84: Pregunta_81 | AG84: B
B85: Pregunta_82 | C85: {=_xlfn.IFS(B$2=1,F85,B$2=2,I85,B$2=3,L85,B$2=4,O85,B$2=5,R85,B$2=6,U85,B$2=7,X85,B$2=8,AA85,B$2=9,AD85,B$2=10,AG85,B$2=11,AJ85)} -> 0 | AF85: Pregunta_82 | AG85: C
B86: Pregunta_83 | C86: {=_xlfn.IFS(B$2=1,F86,B$2=2,I86,B$2=3,L86,B$2=4,O86,B$2=5,R86,B$2=6,U86,B$2=7,X86,B$2=8,AA86,B$2=9,AD86,B$2=10,AG86,B$2=11,AJ86)} -> 0 | AF86: Pregunta_83 | AG86: B
...
